<?xml version="1.0"?>
<robot name="garuda" xmlns:xacro="http://www.ros.org/wiki/xacro">

    <!--
        This file defines the physical properties and structure of the robot.
        It uses simple geometric shapes for visualization and collision.
        This version includes a unique chassis with a "sensor tower" and
        two correctly placed front caster wheels for stability.
    -->

    <!-- Include the materials file for colors -->
    <xacro:include filename="$(find garuda_description)/urdf/materials.xacro" />

    <!-- Include the Gazebo plugins and sensor definitions -->
    <xacro:include filename="$(find garuda_description)/urdf/garuda.gazebo" />

    <!--
        LINKS
        Links describe the physical parts of the robot.
    -->

    <!-- Base Footprint: A non-visual link at the bottom of the robot.
         This is the root of the robot's TF tree. -->
    <link name="base_footprint" />

    <!-- Base Link: The main chassis of the robot. -->
    <link name="base_link">
        <visual>
            <!-- Main Body -->
            <geometry>
                <box size="0.4 0.3 0.08"/>
            </geometry>
            <material name="Blue"/>
        </visual>
        <visual>
            <!-- NEW: Sensor Tower -->
            <origin xyz="0.1 0 0.09" rpy="0 0 0"/>
            <geometry>
                <box size="0.15 0.2 0.1"/>
            </geometry>
            <material name="Grey"/>
        </visual>
        <collision>
            <geometry>
                <box size="0.4 0.3 0.08"/>
            </geometry>
        </collision>
        <collision>
            <origin xyz="0.1 0 0.09" rpy="0 0 0"/>
            <geometry>
                <box size="0.15 0.2 0.1"/>
            </geometry>
        </collision>
        <inertial>
            <origin xyz="0 0 0" rpy="0 0 0"/>
            <mass value="5.0"/>
            <inertia ixx="0.03" ixy="0.0" ixz="0.0" iyy="0.04" iyz="0.0" izz="0.05"/>
        </inertial>
    </link>

    <!-- Right Wheel -->
    <link name="right_wheel_link">
        <visual>
            <origin xyz="0 0 0" rpy="1.5707 0 0"/>
            <geometry>
                <cylinder radius="0.1" length="0.05"/>
            </geometry>
            <material name="Black"/>
        </visual>
        <collision>
            <origin xyz="0 0 0" rpy="1.5707 0 0"/>
            <geometry>
                <cylinder radius="0.1" length="0.05"/>
            </geometry>
        </collision>
        <inertial>
            <origin xyz="0 0 0" rpy="0 0 0"/>
            <mass value="0.5"/>
            <inertia ixx="0.001" ixy="0.0" ixz="0.0" iyy="0.001" iyz="0.0" izz="0.002"/>
        </inertial>
    </link>

    <!-- Left Wheel -->
    <link name="left_wheel_link">
        <visual>
            <origin xyz="0 0 0" rpy="1.5707 0 0"/>
            <geometry>
                <cylinder radius="0.1" length="0.05"/>
            </geometry>
            <material name="Black"/>
        </visual>
        <collision>
            <origin xyz="0 0 0" rpy="1.5707 0 0"/>
            <geometry>
                <cylinder radius="0.1" length="0.05"/>
            </geometry>
        </collision>
        <inertial>
            <origin xyz="0 0 0" rpy="0 0 0"/>
            <mass value="0.5"/>
            <inertia ixx="0.001" ixy="0.0" ixz="0.0" iyy="0.001" iyz="0.0" izz="0.002"/>
        </inertial>
    </link>

    <!-- Front Right Caster Wheel -->
    <link name="caster_front_right_link">
        <visual>
            <geometry>
                <sphere radius="0.04"/>
            </geometry>
            <material name="Black"/>
        </visual>
        <collision>
            <geometry>
                <sphere radius="0.04"/>
            </geometry>
        </collision>
        <inertial>
            <mass value="0.2"/>
            <inertia ixx="0.0001" ixy="0" ixz="0" iyy="0.0001" iyz="0" izz="0.0001"/>
        </inertial>
    </link>

    <!-- Front Left Caster Wheel -->
    <link name="caster_front_left_link">
        <visual>
            <geometry>
                <sphere radius="0.04"/>
            </geometry>
            <material name="Black"/>
        </visual>
        <collision>
            <geometry>
                <sphere radius="0.04"/>
            </geometry>
        </collision>
        <inertial>
            <mass value="0.2"/>
            <inertia ixx="0.0001" ixy="0" ixz="0" iyy="0.0001" iyz="0" izz="0.0001"/>
        </inertial>
    </link>

    <!-- Camera Link: A visible box to represent the camera -->
    <link name="camera_link">
        <visual>
            <geometry>
                <box size="0.04 0.08 0.04"/>
            </geometry>
            <material name="Red"/>
        </visual>
        <collision>
            <geometry>
                <box size="0.04 0.08 0.04"/>
            </geometry>
        </collision>
        <inertial>
            <mass value="0.05"/>
            <inertia ixx="1e-5" ixy="0" ixz="0" iyy="1e-5" iyz="0" izz="1e-5"/>
        </inertial>
    </link>

    <!-- Lidar Link: A visible cylinder to represent the lidar -->
    <link name="lidar_link">
        <visual>
            <geometry>
                <cylinder radius="0.05" length="0.06"/>
            </geometry>
            <material name="Green"/>
        </visual>
        <collision>
            <geometry>
                <cylinder radius="0.05" length="0.06"/>
            </geometry>
        </collision>
        <inertial>
            <mass value="0.1"/>
            <inertia ixx="1e-4" ixy="0" ixz="0" iyy="1e-4" iyz="0" izz="1e-4"/>
        </inertial>
    </link>

    <!-- IMU Link: This link is not visual, its position is what matters. -->
    <link name="imu_link"/>

    <!--
        JOINTS
        Joints connect links together.
    -->

    <!-- Connects base_footprint to base_link -->
    <joint name="base_joint" type="fixed">
        <parent link="base_footprint"/>
        <child link="base_link"/>
        <origin xyz="0.0 0.0 0.1" rpy="0 0 0"/>
    </joint>

    <!-- Connects Right Wheel to Base Link -->
    <joint name="right_wheel_joint" type="continuous">
        <parent link="base_link"/>
        <child link="right_wheel_link"/>
        <origin xyz="-0.05 -0.175 0.0" rpy="0 0 0"/>
        <axis xyz="0 1 0"/>
    </joint>

    <!-- Connects Left Wheel to Base Link -->
    <joint name="left_wheel_joint" type="continuous">
        <parent link="base_link"/>
        <child link="left_wheel_link"/>
        <origin xyz="-0.05 0.175 0.0" rpy="0 0 0"/>
        <axis xyz="0 1 0"/>
    </joint>

    <!-- Connects Front Right Caster to Base Link.
         CORRECTED: Lowered Z-axis to be visible below the chassis. -->
    <joint name="caster_front_right_joint" type="fixed">
        <parent link="base_link"/>
        <child link="caster_front_right_link"/>
        <origin xyz="0.15 -0.1 -0.06" rpy="0 0 0"/>
    </joint>

    <!-- Connects Front Left Caster to Base Link.
         CORRECTED: Lowered Z-axis to be visible below the chassis. -->
    <joint name="caster_front_left_joint" type="fixed">
        <parent link="base_link"/>
        <child link="caster_front_left_link"/>
        <origin xyz="0.15 0.1 -0.06" rpy="0 0 0"/>
    </joint>

    <!-- Connects Camera to Base Link on the sensor tower -->
    <joint name="camera_joint" type="fixed">
        <parent link="base_link"/>
        <child link="camera_link"/>
        <!-- CORRECTED: Moved camera to the front face of the sensor tower -->
        <origin xyz="0.195 0 0.11" rpy="0 0 0"/>
    </joint>

    <!-- Connects Lidar to Base Link on top of the sensor tower -->
    <joint name="lidar_joint" type="fixed">
        <parent link="base_link"/>
        <child link="lidar_link"/>
        <origin xyz="0.05 0 0.17" rpy="0 0 0"/>
    </joint>

    <!-- Connects IMU to Base Link -->
    <joint name="imu_joint" type="fixed">
        <parent link="base_link"/>
        <child link="imu_link"/>
        <origin xyz="0 0 0" rpy="0 0 0"/>
    </joint>

</robot>